Workbook

Sheet Dados
A1: Projeto | B1: Descrição do Projeto | C1: Data Programacao | D1: Status Programacao | E1: Tipo Intervencao | F1: Numero PowerON | G1: Equipamentos | H1: Regiao | I1: CHI | J1: Horario Inicio | K1: Horario Fim | L1: Contratada
A2: DMP/A.SUL.26.06607 | B2: =_xlfn.XLOOKUP(A:A,Planilha1!A:A,Planilha1!D:D,"Não encontrado") -> Poda de Árvores | C2: 46317 | D2: Liberado para Execução | E2: FI | F2: 16948200 | G2: 256ET033820 | H2: =_xlfn.XLOOKUP(A:A,Planilha1!A:A,Planilha1!F:F,"Não encontrado") -> Sul | I2: 384 | J2: 46317.375 | K2: 46317.542 | L2: AP+Eletro Light Poda NEC
A3: DMP/A.ABC.26.02254 | B3: =_xlfn.XLOOKUP(A:A,Planilha1!A:A,Planilha1!D:D,"Não encontrado") -> Poda de Árvores | C3: 46317 | D3: Liberado para Execução | E3: FI | F3: 16943884 | G3: 035ET041988 | H3: =_xlfn.XLOOKUP(A:A,Planilha1!A:A,Planilha1!F:F,"Não encontrado") -> ABC | I3: 188 | J3: 46317.375 | K3: 46317.542 | L3: AP+Eletro Light Poda NEC
A4: DMP/A.LES.25.06403 | B4: =_xlfn.XLOOKUP(A:A,Planilha1!A:A,Planilha1!D:D,"Não encontrado") -> Reforma de Rede Secundaria RTRI | C4: 46317 | D4: Liberado para Execução | E4: FI | F4: 16943931 | G4: 356ET007318 | H4: =_xlfn.XLOOKUP(A:A,Planilha1!A:A,Planilha1!F:F,"Não encontrado") -> LES | I4: 564 | J4: 46317.375 | K4: 46317.542 | L4: Enel SP - Monte Santo
A5: DMP/A.LES.25.06946 | B5: =_xlfn.XLOOKUP(A:A,Planilha1!A:A,Planilha1!D:D,"Não encontrado") -> Reforma de Rede Secundaria RTRI | C5: 46317 | D5: Liberado para Execução | E5: FI | F5: 16943931 | G5: 356ET007318 | H5: =_xlfn.XLOOKUP(A:A,Planilha1!A:A,Planilha1!F:F,"Não encontrado") -> LES | I5: 564 | J5: 46317.375 | K5: 46317.542 | L5: Enel SP - Monte Santo
A6: DMP/A.SUL.26.07228 | B6: =_xlfn.XLOOKUP(A:A,Planilha1!A:A,Planilha1!D:D,"Não encontrado") -> Poda de Árvores | C6: 46317 | D6: Liberado para Execução | E6: FI | F6: 16966831 | G6: 252ET062593; 252BF064313 | H6: =_xlfn.XLOOKUP(A:A,Planilha1!A:A,Planilha1!F:F,"Não encontrado") -> Sul | I6: 1604 | J6: 46317.375 | K6: 46317.542 | L6: AP+Eletro Light Poda NEC
A7: DAC/A.OES.26.00764 | B7: =_xlfn.XLOOKUP(A:A,Planilha1!A:A,Planilha1!D:D,"Não encontrado") -> Ligação Nova | C7: 46317 | D7: Liberado para Execução | E7: BRA | F7: 16936630 | G7: 085ET246592 | H7: =_xlfn.XLOOKUP(A:A,Planilha1!A:A,Planilha1!F:F,"Não encontrado") -> oes | I7: 0 | J7: 46317.417 | K7: 46317.625 | L7: Cena-Land Aéreo (Área 1, 2+3 e 6) UPS
A8: DMP/A.LES.26.06440 | B8: =_xlfn.XLOOKUP(A:A,Planilha1!A:A,Planilha1!D:D,"Não encontrado") -> Poda de Árvores | C8: 46317 | D8: Cancelado | E8: PIE | F8: RESOLVIDO | G8: 355ET012493 | H8: =_xlfn.XLOOKUP(A:A,Planilha1!A:A,Planilha1!F:F,"Não encontrado") -> LES | I8: 172 | J8: 46317.375 | K8: 46317.542 | L8: AP+ELETTRO LIGHT CONSULTORIA,
A9: DMP/A.OES.26.01916 | B9: =_xlfn.XLOOKUP(A:A,Planilha1!A:A,Planilha1!D:D,"Não encontrado") -> Segurança Operativa | C9: 46317 | D9: Liberado para Execução | E9: FI | F9: 16948515 | G9: 105ET060993 | H9: =_xlfn.XLOOKUP(A:A,Planilha1!A:A,Planilha1!F:F,"Não encontrado") -> oes | I9: 240 | J9: 46317.458 | K9: 46317.625 | L9: BTobace Obras (Área 1,2+3 e 6) NEC
A10: DAC/A.ABC.26.00036 | B10: =_xlfn.XLOOKUP(A:A,Planilha1!A:A,Planilha1!D:D,"Não encontrado") -> Remoção de Poste | C10: 46317 | D10: Liberado para Execução | E10: PIE | F10: 16909486 | G10: 010ET003818 | H10: =_xlfn.XLOOKUP(A:A,Planilha1!A:A,Planilha1!F:F,"Não encontrado") -> ABC | I10: 56 | J10: 46317.979 | K10: 46318.146 | L10: Start Engenharia (Área 8B, 9 e 11) NEC
A11: DAC/A.ABC.26.00029 | B11: =_xlfn.XLOOKUP(A:A,Planilha1!A:A,Planilha1!D:D,"Não encontrado") -> Remoção de Poste | C11: 46317 | D11: Liberado para Execução | E11: FI | F11: 16944434 | G11: 030ET007283 | H11: =_xlfn.XLOOKUP(A:A,Planilha1!A:A,Planilha1!F:F,"Não encontrado") -> ABC | I11: 156 | J11: 46317.396 | K11: 46317.562 | L11: TEES Engenharia (Áreas 7, 8A e 10) NEC
A12: DMP/A.OES.26.04458 | B12: =_xlfn.XLOOKUP(A:A,Planilha1!A:A,Planilha1!D:D,"Não encontrado") -> Rede Compacta | C12: 46317 | D12: Liberado para Execução | E12: FI | F12: 16948159 | G12: ET-031746 | H12: =_xlfn.XLOOKUP(A:A,Planilha1!A:A,Planilha1!F:F,"Não encontrado") -> oes | I12: 64 | J12: 46317.5 | K12: 46317.667 | L12: Cena-Land Aéreo (Área 1, 2+3 e 6) UPS
A13: DAC/A.LES.26.01126 | B13: =_xlfn.XLOOKUP(A:A,Planilha1!A:A,Planilha1!D:D,"Não encontrado") -> Ligação Nova | C13: 46317 | D13: Liberado para Execução | E13: PIE | F13: 16936764 | G13: 356ET162584 | H13: =_xlfn.XLOOKUP(A:A,Planilha1!A:A,Planilha1!F:F,"Não encontrado") -> LES | I13: 72 | J13: 46317.396 | K13: 46317.562 | L13: Start Engenharia (Área 8B, 9 e 11) NEC
... A66: DAC/A.NOR.25.01320 | B66: =_xlfn.XLOOKUP(A:A,Planilha1!A:A,Planilha1!D:D,"Não encontrado") -> Ligação Nova | C66: 46317 | D66: Liberado para Execução | E66: BRA | F66: 16970482 | G66: DJSAM0102 | H66: =_xlfn.XLOOKUP(A:A,Planilha1!A:A,Planilha1!F:F,"Não encontrado") -> NOR | I66: 0 | J66: 46317.333 | K66: 46317.708 | L66: Conecta Obras (Área 4 e 5) NEC
A67: DAC/A.SUL.26.00475 | B67: =_xlfn.XLOOKUP(A:A,Planilha1!A:A,Planilha1!D:D,"Não encontrado") -> Remoção de Poste | C67: 46317 | D67: Liberado para Execução | E67: OLVR | G67: 256ET098552 | H67: =_xlfn.XLOOKUP(A:A,Planilha1!A:A,Planilha1!F:F,"Não encontrado") -> Sul | I67: 0 | J67: 46317.375 | K67: 46317.667 | L67: Alpitel Energy (Área 7, 8A e 10) NEC
A68: DAC/A.SUL.25.01209 | B68: =_xlfn.XLOOKUP(A:A,Planilha1!A:A,Planilha1!D:D,"Não encontrado") -> Afastamento de Rede (Clientes) | C68: 46317 | D68: Liberado para Execução | E68: BRA | F68: 16996830 | G68: 256BF063129 | H68: =_xlfn.XLOOKUP(A:A,Planilha1!A:A,Planilha1!F:F,"Não encontrado") -> Sul | I68: 0 | J68: 46317.375 | K68: 46317.667 | L68: Alpitel Energy (Área 7, 8A e 10) NEC
A69: DMP/A.SUL.25.07763 | B69: =_xlfn.XLOOKUP(A:A,Planilha1!A:A,Planilha1!D:D,"Não encontrado") -> Religador Automático | C69: 46317 | D69: Liberado para Execução | E69: FI | F69: 16977200 | G69: 355ET007141 | H69: =_xlfn.XLOOKUP(A:A,Planilha1!A:A,Planilha1!F:F,"Não encontrado") -> Sul | I69: 224 | J69: 46317.438 | K69: 46317.604 | L69: Alpitel Energy (Área 7, 8A e 10) NEC
A70: DMP/A.LES.26.02040 | B70: =_xlfn.XLOOKUP(A:A,Planilha1!A:A,Planilha1!D:D,"Não encontrado") -> Reforma de Rede Secundária | C70: 46317 | D70: Liberado para Execução | E70: FI | F70: 16977200 | G70: 355ET025695 | H70: =_xlfn.XLOOKUP(A:A,Planilha1!A:A,Planilha1!F:F,"Não encontrado") -> LES | I70: 500 | J70: 46317.438 | K70: 46317.604 | L70: ZZOUT-PSC Alpitel Área 9
A71: DMP/A.LES.12.01197 | B71: =_xlfn.XLOOKUP(A:A,Planilha1!A:A,Planilha1!D:D,"Não encontrado") -> Manutenção de Redes e Linhas Aéreas | C71: 46317 | D71: Liberado para Execução | E71: FI | F71: 16947836 | G71: 353ET170724 | H71: =_xlfn.XLOOKUP(A:A,Planilha1!A:A,Planilha1!F:F,"Não encontrado") -> LES | I71: 0 | J71: 46317.001 | K71: 46317.167 | L71: Enel SP - Diadema
A72: DAC/A.OES.26.00914 | B72: =_xlfn.XLOOKUP(A:A,Planilha1!A:A,Planilha1!D:D,"Não encontrado") -> Ligação Nova | C72: 46317 | D72: Liberado para Execução | E72: BRA | F72: 16964424 | G72: 252ET101315 | H72: =_xlfn.XLOOKUP(A:A,Planilha1!A:A,Planilha1!F:F,"Não encontrado") -> oes | I72: 0 | J72: 46317.375 | K72: 46317.667 | L72: BTobace Obras (Área 1,2+3 e 6) NEC
A73: DAC/A.OES.26.00914 | B73: =_xlfn.XLOOKUP(A:A,Planilha1!A:A,Planilha1!D:D,"Não encontrado") -> Ligação Nova | C73: 46317 | D73: Liberado para Execução | E73: BRA | F73: 16976852 | G73: 252ET100122 | H73: =_xlfn.XLOOKUP(A:A,Planilha1!A:A,Planilha1!F:F,"Não encontrado") -> oes | I73: 0 | J73: 46317.375 | K73: 46317.667 | L73: BTobace Obras (Área 1,2+3 e 6) NEC
A74: DMP/A.SUL.26.07200 | B74: =_xlfn.XLOOKUP(A:A,Planilha1!A:A,Planilha1!D:D,"Não encontrado") -> Rede Compacta | C74: 46317 | D74: Liberado para Execução | E74: FI | F74: 16983132 | G74: 256BF062823 | H74: =_xlfn.XLOOKUP(A:A,Planilha1!A:A,Planilha1!F:F,"Não encontrado") -> Sul | I74: 244 | J74: 46317.458 | K74: 46317.625 | L74: PSE Engenharia (Área 7, 8A e 10) NEC
A75: DMP/A.SUL.26.07333 | B75: =_xlfn.XLOOKUP(A:A,Planilha1!A:A,Planilha1!D:D,"Não encontrado") -> Rede Compacta | C75: 46317 | D75: Liberado para Execução | E75: FI | F75: 16983132 | G75: 256BF062823 | H75: =_xlfn.XLOOKUP(A:A,Planilha1!A:A,Planilha1!F:F,"Não encontrado") -> Sul | I75: 244 | J75: 46317.458 | K75: 46317.625 | L75: PSE Engenharia (Área 7, 8A e 10) NEC
A76: DMP/A.SUL.26.07466 | B76: =_xlfn.XLOOKUP(A:A,Planilha1!A:A,Planilha1!D:D,"Não encontrado") -> Rede Compacta | C76: 46317 | D76: Liberado para Execução | E76: FI | F76: 16983132 | G76: 256BF062823 | H76: =_xlfn.XLOOKUP(A:A,Planilha1!A:A,Planilha1!F:F,"Não encontrado") -> Sul | I76: 244 | J76: 46317.458 | K76: 46317.625 | L76: PSE Engenharia (Área 7, 8A e 10) NEC
A77: DMP/A.SUL.26.07199 | B77: =_xlfn.XLOOKUP(A:A,Planilha1!A:A,Planilha1!D:D,"Não encontrado") -> Rede Compacta | C77: 46317 | D77: Liberado para Execução | E77: FI | F77: 16983132 | G77: 256BF062823 | H77: =_xlfn.XLOOKUP(A:A,Planilha1!A:A,Planilha1!F:F,"Não encontrado") -> Sul | I77: 244 | J77: 46317.458 | K77: 46317.625 | L77: PSE Engenharia (Área 7, 8A e 10) NEC
A78: DMP/A.ABC.26.00224 | B78: =_xlfn.XLOOKUP(A:A,Planilha1!A:A,Planilha1!D:D,"Não encontrado") -> Poda de Árvores | C78: 46317 | D78: Cancelado | E78: FI | F78: DEVOLVIDO | G78: 035BF034710 | H78: =_xlfn.XLOOKUP(A:A,Planilha1!A:A,Planilha1!F:F,"Não encontrado") -> ABC | I78: 476 | J78: 46317.375 | K78: 46317.542 | L78: AP+Eletro Light Poda NEC
A79: DMP/A.ABC.26.00007 | B79: =_xlfn.XLOOKUP(A:A,Planilha1!A:A,Planilha1!D:D,"Não encontrado") -> Poda de Árvores | C79: 46317 | D79: Cancelado | E79: FI | F79: DEVOLVIDO | G79: 035ET041723 | H79: =_xlfn.XLOOKUP(A:A,Planilha1!A:A,Planilha1!F:F,"Não encontrado") -> ABC | I79: 272 | J79: 46317.375 | K79: 46317.542 | L79: AP+Eletro Light Poda NEC
... A114: DMP/A.SUL.26.05338 | B114: =_xlfn.XLOOKUP(A:A,Planilha1!A:A,Planilha1!D:D,"Não encontrado") -> Poda de Árvores | C114: 46317 | D114: Liberado para Execução | E114: BRA | F114: 17001800 | G114: 151CT000506 | H114: =_xlfn.XLOOKUP(A:A,Planilha1!A:A,Planilha1!F:F,"Não encontrado") -> Sul | I114: 0 | J114: 46317.292 | K114: 46317.75 | L114: BTobace Obras (Área 1,2+3 e 6) PODA
A115: DMP/A.NOR.26.03775 | B115: =_xlfn.XLOOKUP(A:A,Planilha1!A:A,Planilha1!D:D,"Não encontrado") -> Religador Automático | C115: 46317 | D115: Rascunho | E115: BRA | G115: 151ET014997 | H115: =_xlfn.XLOOKUP(A:A,Planilha1!A:A,Planilha1!F:F,"Não encontrado") -> NOR | I115: 0 | J115: 46317.333 | K115: 46317.708 | L115: Enel SP - Fagundes Filho
A116: DMP/A.OES.26.07227 | B116: =_xlfn.XLOOKUP(A:A,Planilha1!A:A,Planilha1!D:D,"Não encontrado") -> Poda de Árvores | C116: 46317 | D116: Liberado para Execução | E116: BRA | F116: 17001698-1 | G116: CT-000506 | H116: =_xlfn.XLOOKUP(A:A,Planilha1!A:A,Planilha1!F:F,"Não encontrado") -> oes | I116: 0 | J116: 46317.292 | K116: 46317.75 | L116: BTobace Obras (Área 1,2+3 e 6) PODA
A117: DMP/A.OES.26.07252 | B117: =_xlfn.XLOOKUP(A:A,Planilha1!A:A,Planilha1!D:D,"Não encontrado") -> Poda de Árvores | C117: 46317 | D117: Pendente de Aprovação | E117: BRA | G117: CT-000506 | H117: =_xlfn.XLOOKUP(A:A,Planilha1!A:A,Planilha1!F:F,"Não encontrado") -> oes | I117: 0 | J117: 46317.292 | K117: 46317.75 | L117: BTobace Obras (Área 1,2+3 e 6) PODA
A118: DMP/A.ABC.26.01026 | B118: =_xlfn.XLOOKUP(A:A,Planilha1!A:A,Planilha1!D:D,"Não encontrado") -> Poda de Árvores | C118: 46317 | D118: Liberado para Execução | E118: BRA | F118: 16993303-1 | G118: 035ET028486 | H118: =_xlfn.XLOOKUP(A:A,Planilha1!A:A,Planilha1!F:F,"Não encontrado") -> ABC | I118: 0 | J118: 46317.292 | K118: 46317.708 | L118: AP+ELETTRO LIGHT CONSULTORIA,
A119: DMP/A.SUL.26.04534 | B119: =_xlfn.XLOOKUP(A:A,Planilha1!A:A,Planilha1!D:D,"Não encontrado") -> Poda de Árvores | C119: 46317 | D119: Liberado para Execução | E119: BRA | F119: 17001571 | G119: 151CT000506 | H119: =_xlfn.XLOOKUP(A:A,Planilha1!A:A,Planilha1!F:F,"Não encontrado") -> Sul | I119: 0 | J119: 46317.292 | K119: 46317.75 | L119: BTobace Obras (Área 1,2+3 e 6) PODA
A120: DMP/A.ABC.26.03225 | B120: =_xlfn.XLOOKUP(A:A,Planilha1!A:A,Planilha1!D:D,"Não encontrado") -> Poda de Árvores | C120: 46317 | D120: Liberado para Execução | E120: BRA | F120: 16996154-1 | G120: 030ET029814 | H120: =_xlfn.XLOOKUP(A:A,Planilha1!A:A,Planilha1!F:F,"Não encontrado") -> ABC | I120: 0 | J120: 46317.292 | K120: 46317.708 | L120: AP+ELETTRO LIGHT CONSULTORIA,
A121: DMP/A.ABC.26.03205 | B121: =_xlfn.XLOOKUP(A:A,Planilha1!A:A,Planilha1!D:D,"Não encontrado") -> Poda de Árvores | C121: 46317 | D121: Liberado para Execução | E121: BRA | F121: 16996154-1 | G121: 030ET005500 | H121: =_xlfn.XLOOKUP(A:A,Planilha1!A:A,Planilha1!F:F,"Não encontrado") -> ABC | I121: 0 | J121: 46317.292 | K121: 46317.708 | L121: AP+ELETTRO LIGHT CONSULTORIA,
A122: DMP/A.ABC.26.03230 | B122: =_xlfn.XLOOKUP(A:A,Planilha1!A:A,Planilha1!D:D,"Não encontrado") -> Poda de Árvores | C122: 46317 | D122: Liberado para Execução | E122: BRA | F122: 16996263-1 | G122: 030ET015335 | H122: =_xlfn.XLOOKUP(A:A,Planilha1!A:A,Planilha1!F:F,"Não encontrado") -> ABC | I122: 0 | J122: 46317.292 | K122: 46317.708 | L122: AP+ELETTRO LIGHT CONSULTORIA,
A123: DMP/A.SUL.26.06110 | B123: =_xlfn.XLOOKUP(A:A,Planilha1!A:A,Planilha1!D:D,"Não encontrado") -> Poda de Árvores | C123: 46317 | D123: Liberado para Execução | E123: BRA | F123: 17001333 | G123: 151CT000506 | H123: =_xlfn.XLOOKUP(A:A,Planilha1!A:A,Planilha1!F:F,"Não encontrado") -> Sul | I123: 0 | J123: 46317.292 | K123: 46317.75 | L123: BTobace Obras (Área 1,2+3 e 6) PODA
A124: DMP/A.ABC.26.01804 | B124: =_xlfn.XLOOKUP(A:A,Planilha1!A:A,Planilha1!D:D,"Não encontrado") -> Poda de Árvores | C124: 46317 | D124: Liberado para Execução | E124: BRA | F124: 16997152-1 | G124: 035ET233406 | H124: =_xlfn.XLOOKUP(A:A,Planilha1!A:A,Planilha1!F:F,"Não encontrado") -> ABC | I124: 0 | J124: 46317.292 | K124: 46317.708 | L124: AP+ELETTRO LIGHT CONSULTORIA,
A125: DMP/A.ABC.26.03247 | B125: =_xlfn.XLOOKUP(A:A,Planilha1!A:A,Planilha1!D:D,"Não encontrado") -> Poda de Árvores | C125: 46317 | D125: Liberado para Execução | E125: BRA | F125: 16996344-1 | G125: 030IP012134 | H125: =_xlfn.XLOOKUP(A:A,Planilha1!A:A,Planilha1!F:F,"Não encontrado") -> ABC | I125: 0 | J125: 46317.292 | K125: 46317.708 | L125: AP+ELETTRO LIGHT CONSULTORIA,
A126: DMP/A.ABC.26.02739 | B126: =_xlfn.XLOOKUP(A:A,Planilha1!A:A,Planilha1!D:D,"Não encontrado") -> Poda de Árvores | C126: 46317 | D126: Liberado para Execução | E126: BRA | F126: 16996492-1 | G126: 035ET227334 | H126: =_xlfn.XLOOKUP(A:A,Planilha1!A:A,Planilha1!F:F,"Não encontrado") -> ABC | I126: 0 | J126: 46317.292 | K126: 46317.708 | L126: AP+ELETTRO LIGHT CONSULTORIA,
...

Sheet Planilha1
A1: Projeto | B1: Nota | C1: Empresa Executante | D1: Descrição do Projeto | E1: Rua | F1: Regiao | G1: Pendente | H1: UPS Orçada | I1: Status do Projeto | J1: Priorizado | K1: Prioritario | L1: Data da Priorizacao | M1: Motivo da Priorizacao
A2: DAC/A.ABC.26.00003 | B2: 389399916 | C2: Start Engenharia (Área 8B, 9 e 11) NEC | D2: Migração para Média Tensão | E2: Rua Rio Grande | F2: ABC | G2: 155 | H2: 52.695 | I2: Atendido | J2: TRUE | K2: FALSE
A3: DAC/A.ABC.26.00014 | B3: 389575327 | C3: TEES Engenharia (Áreas 7, 8A e 10) NEC | D3: Ligação Nova | E3: Rodovia dos Imigrantes | F3: ABC | G3: 86 | H3: 25.097 | I3: Atendido | J3: TRUE | K3: FALSE
A4: DAC/A.ABC.26.00029 | C4: TEES Engenharia (Áreas 7, 8A e 10) NEC | D4: Remoção de Poste | E4: Rua Aquidaban | F4: ABC | G4: 92 | H4: 73.373 | I4: Programado | J4: TRUE | K4: FALSE
A5: DAC/A.ABC.26.00036 | B5: 391171495 | C5: Start Engenharia (Área 8B, 9 e 11) NEC | D5: Remoção de Poste | E5: Avenida Pereira Barreto | Praça Ives Ota | F5: ABC | G5: 53 | H5: 67.063 | I5: Programado | J5: TRUE | K5: FALSE
A6: DAC/A.ABC.26.00038 | C6: TEES Engenharia (Áreas 7, 8A e 10) NEC | D6: Alteração de Carga | E6: 00 | F6: ABC | G6: 158 | H6: 83.93 | I6: Programado | J6: TRUE | K6: FALSE
A7: DAC/A.ABC.26.00053 | C7: Start Engenharia (Área 8B, 9 e 11) NEC | D7: Ligação Provisória | F7: ABC | G7: 146 | H7: 109.265 | I7: Programado | J7: TRUE | K7: FALSE
A8: DAC/A.ABC.26.00079 | C8: Start Engenharia (Área 8B, 9 e 11) NEC | D8: Alteração de Carga | E8: Rua Alonso Vasconcelos Pacheco | Avenida Itapark | F8: ABC | G8: 156 | H8: 136.392 | I8: Programado | J8: TRUE | K8: FALSE
A9: DAC/A.ABC.26.00095 | B9: 390172057 | C9: Conecta Obras Extras (Área 8B, 9 e 11) NEC | D9: Migração para Média Tensão | E9: Rua Doutor Ulysses Guimarães | F9: ABC | G9: 148 | H9: 30.377 | I9: Programado | J9: TRUE | K9: FALSE
A10: DAC/A.ABC.26.00108 | B10: 3639474 | C10: Cena-Land Subterrâneo | D10: Remoção de Posto Primário | F10: ABC | G10: 119 | H10: 0 | I10: Programado | J10: TRUE | K10: FALSE
A11: DAC/A.ABC.26.00110 | B11: 3639272 | C11: Cena-Land Subterrâneo | D11: Remoção de Posto Primário | F11: ABC | G11: 84 | H11: 0 | I11: Programado | J11: TRUE | K11: FALSE
A12: DAC/A.ABC.26.00113 | B12: 3639275 | C12: Cena-Land Subterrâneo | D12: Remoção de Posto Primário | F12: ABC | G12: 84 | H12: 0 | I12: Programado | J12: TRUE | K12: FALSE
A13: DAC/A.ABC.26.00125 | B13: 3639788 | C13: Cena-Land Subterrâneo | D13: Remoção de Posto Primário | F13: ABC | G13: 79 | H13: 0 | I13: Programado | J13: TRUE | K13: FALSE
A14: DAC/A.ABC.26.00136 | B14: 3639799 | C14: Cena-Land Subterrâneo | D14: Remoção de Posto Primário | F14: ABC | G14: 71 | H14: 0 | I14: Programado | J14: TRUE | K14: FALSE
A15: DAC/A.ABC.26.00138 | B15: 3639801 | C15: Cena-Land Subterrâneo | D15: Remoção de Posto Primário | F15: ABC | G15: 67 | H15: 0 | I15: Programado | J15: TRUE | K15: FALSE
A16: DAC/A.ABC.26.00139 | B16: 3639802 | C16: Cena-Land Subterrâneo | D16: Remoção de Posto Primário | F16: ABC | G16: 71 | H16: 0 | I16: Programado | J16: TRUE | K16: FALSE
A17: DAC/A.ABC.26.00152 | B17: 3639816 | C17: Cena-Land Subterrâneo | D17: Remoção de Posto Primário | F17: ABC | G17: 76 | H17: 0 | I17: Programado | J17: TRUE | K17: FALSE
A18: DAC/A.ABC.26.00154 | B18: 3640016 | C18: TEES Engenharia (Áreas 7, 8A e 10) NEC | D18: Regularização de Ligações Informais | E18: Rua Catequese | Rua Santa Clara | Rua Vanguarda | Rua Pio Gionotte | F18: ABC | G18: 99 | H18: 436.197 | I18: Programado | J18: TRUE | K18: FALSE
A19: DAC/A.ABC.26.00174 | C19: TEES Engenharia (Áreas 7, 8A e 10) NEC | D19: Remoção de Poste | E19: 00 | F19: ABC | G19: 113 | H19: 40.465 | I19: Programado | J19: TRUE | K19: FALSE
A20: DAC/A.ABC.26.00183 | B20: 390596914 | C20: Start Engenharia (Área 8B, 9 e 11) NEC | D20: Alteração de Carga | E20: Rua Doutor Eduardo Monteiro | Rua Doutor Eduardo Monteiro, 410 | Rua São Tomás | F20: ABC | G20: 86 | H20: 39.198 | I20: Programado | J20: TRUE | K20: FALSE
A21: DAC/A.ABC.26.00370 | C21: Start Engenharia (Área 8B, 9 e 11) NEC | D21: Alteração de Carga | F21: ABC | G21: 101 | H21: 60.934 | I21: Programado | J21: TRUE | K21: FALSE
A22: DAC/A.ABC.26.00375 | C22: Start Engenharia (Área 8B, 9 e 11) NEC | D22: Ligação Nova | E22: Avenida Lino Jardim, 884 | Avenida Lino Jardim | F22: ABC | G22: 84 | H22: 45.421 | I22: Programado | J22: TRUE | K22: FALSE
A23: DAC/A.ABC.26.00386 | C23: TEES Engenharia (Áreas 7, 8A e 10) NEC | D23: Migração para Média Tensão | F23: ABC | G23: 86 | H23: 181.168 | I23: Programado | J23: TRUE | K23: FALSE
A24: DAC/A.ABC.26.00402 | C24: Start Engenharia (Área 8B, 9 e 11) NEC | D24: Ligação Nova | E24: Rua do Amaro | Avenida Capitão Mário Toledo de Camargo | Passarela Deputado José Mendes Botelho | Avenida Dom Pedro I, 3000 | F24: ABC | G24: 91 | H24: 125.543 | I24: Programado | J24: TRUE | K24: FALSE
A25: DAC/A.ABC.26.00404 | B25: 391157051 | C25: Start Engenharia (Área 8B, 9 e 11) NEC | D25: Ligação Nova | E25: Rua das Hortências | F25: ABC | G25: 72 | H25: 58.913 | I25: Programado | J25: TRUE | K25: FALSE
A26: DAC/A.ABC.26.00417 | B26: 391225541 | C26: Start Engenharia (Área 8B, 9 e 11) NEC | D26: Alteração de Carga | F26: ABC | G26: 31 | H26: 87.02 | I26: Programado | J26: TRUE | K26: FALSE
A27: DAC/A.ABC.26.00419 | B27: 391241049 | C27: Start Engenharia (Área 8B, 9 e 11) NEC | D27: Alteração de Carga | F27: ABC | G27: 32 | H27: 127.1 | I27: Programado | J27: TRUE | K27: FALSE
A28: DAC/A.ABC.26.00422 | B28: 391245598 | C28: Start Engenharia (Área 8B, 9 e 11) NEC | D28: Ligação Nova | F28: ABC | G28: 37 | H28: 236.263 | I28: Programado | J28: TRUE | K28: FALSE
A29: DAC/A.ABC.26.00426 | B29: 3648274 | C29: Cena-Land Subterrâneo | D29: Remoção de Posto Primário | F29: ABC | G29: 93 | H29: 0 | I29: Programado | J29: TRUE | K29: FALSE
A30: DAC/A.ABC.26.00436 | B30: 3640016 | C30: TEES Engenharia (Áreas 7, 8A e 10) NEC | D30: Regularização de Ligações Informais | F30: ABC | G30: 99 | H30: 3.922 | I30: Programado | J30: TRUE | K30: FALSE
A31: DAC/A.ABC.26.00437 | B31: 391278543 | C31: TEES Engenharia (Áreas 7, 8A e 10) NEC | D31: Ligação Nova | F31: ABC | G31: 77 | H31: 172.913 | I31: Programado | J31: TRUE | K31: FALSE
A32: DAC/A.ABC.26.00438 | B32: 3648821 | C32: Cena-Land Subterrâneo | D32: Remoção de Posto Primário | F32: ABC | G32: 51 | H32: 0 | I32: Programado | J32: TRUE | K32: FALSE
A33: DAC/A.ABC.26.00443 | B33: 3648825 | C33: Cena-Land Subterrâneo | D33: Remoção de Posto Primário | F33: ABC | G33: 62 | H33: 0 | I33: Programado | J33: TRUE | K33: FALSE
A34: DAC/A.ABC.26.00453 | B34: 391547284 | C34: TEES Engenharia (Áreas 7, 8A e 10) NEC | D34: Ligação Nova | F34: ABC | G34: 66 | H34: 20.753 | I34: Programado | J34: TRUE | K34: FALSE
A35: DAC/A.ABC.26.00459 | B35: 391256405 | C35: Start Engenharia (Área 8B, 9 e 11) NEC | D35: Ligação Nova | E35: Avenida Portugal, 1571 | Avenida Portugal, 1555 | Avenida Portugal, 1580 | Rua Galeão Carvalhal | Avenida Portugal | F35: ABC | G35: 70 | H35: 131.317 | I35: Programado | J35: TRUE | K35: FALSE
A36: DAC/A.ABC.26.00464 | B36: 391612156 | C36: Start Engenharia (Área 8B, 9 e 11) NEC | D36: Ligação Nova | E36: Rua Miguel Prisco | F36: ABC | G36: 58 | H36: 65.45 | I36: Programado | J36: TRUE | K36: FALSE
A37: DAC/A.ABC.26.00474 | B37: 391740778 | C37: TEES Engenharia (Áreas 7, 8A e 10) NEC | D37: Migração para Média Tensão | E37: Estrada do Vergueiro, 76 | F37: ABC | G37: 65 | H37: 35.189 | I37: Programado | J37: TRUE | K37: FALSE
A38: DAC/A.ABC.26.00475 | B38: 391753409 | C38: Start Engenharia (Área 8B, 9 e 11) NEC | D38: Alteração de Carga | E38: Rua Baia Blanca | F38: ABC | G38: 43 | H38: 43.436 | I38: Programado | J38: TRUE | K38: FALSE
A39: DAC/A.ABC.26.00481 | B39: 3651377 | C39: Cena-Land Subterrâneo | D39: Remoção de Posto Primário | F39: ABC | G39: 62 | H39: 0 | I39: Programado | J39: TRUE | K39: FALSE
A40: DAC/A.ABC.26.00490 | B40: 3651438 | C40: Cena-Land Subterrâneo | D40: Remoção de Posto Primário | F40: ABC | G40: 62 | H40: 0 | I40: Programado | J40: TRUE | K40: FALSE
...
